{"id":"node_modules/rxjs-compat/operator/catch.js","dependencies":[{"name":"/Users/haimagami/Desktop/personal-site/node_modules/rxjs-compat/operator/catch.js.map","includedInParent":true,"mtime":1558549199495},{"name":"/Users/haimagami/Desktop/personal-site/package.json","includedInParent":true,"mtime":1558549229172},{"name":"/Users/haimagami/Desktop/personal-site/node_modules/rxjs-compat/package.json","includedInParent":true,"mtime":1558549199495},{"name":"rxjs/operators","loc":{"line":3,"column":26},"parent":"/Users/haimagami/Desktop/personal-site/node_modules/rxjs-compat/operator/catch.js","resolved":"/Users/haimagami/Desktop/personal-site/node_modules/rxjs/_esm5/operators/index.js"}],"generated":{"js":"\"use strict\";\nObject.defineProperty(exports, \"__esModule\", { value: true });\nvar operators_1 = require(\"rxjs/operators\");\n/**\n * Catches errors on the observable to be handled by returning a new observable or throwing an error.\n *\n * <img src=\"./img/catch.png\" width=\"100%\">\n *\n * @example <caption>Continues with a different Observable when there's an error</caption>\n *\n * Observable.of(1, 2, 3, 4, 5)\n *   .map(n => {\n * \t   if (n == 4) {\n * \t     throw 'four!';\n *     }\n *\t   return n;\n *   })\n *   .catch(err => Observable.of('I', 'II', 'III', 'IV', 'V'))\n *   .subscribe(x => console.log(x));\n *   // 1, 2, 3, I, II, III, IV, V\n *\n * @example <caption>Retries the caught source Observable again in case of error, similar to retry() operator</caption>\n *\n * Observable.of(1, 2, 3, 4, 5)\n *   .map(n => {\n * \t   if (n === 4) {\n * \t     throw 'four!';\n *     }\n * \t   return n;\n *   })\n *   .catch((err, caught) => caught)\n *   .take(30)\n *   .subscribe(x => console.log(x));\n *   // 1, 2, 3, 1, 2, 3, ...\n *\n * @example <caption>Throws a new error when the source Observable throws an error</caption>\n *\n * Observable.of(1, 2, 3, 4, 5)\n *   .map(n => {\n *     if (n == 4) {\n *       throw 'four!';\n *     }\n *     return n;\n *   })\n *   .catch(err => {\n *     throw 'error in source. Details: ' + err;\n *   })\n *   .subscribe(\n *     x => console.log(x),\n *     err => console.log(err)\n *   );\n *   // 1, 2, 3, error in source. Details: four!\n *\n * @param {function} selector a function that takes as arguments `err`, which is the error, and `caught`, which\n *  is the source observable, in case you'd like to \"retry\" that observable by returning it again. Whatever observable\n *  is returned by the `selector` will be used to continue the observable chain.\n * @return {Observable} An observable that originates from either the source or the observable returned by the\n *  catch `selector` function.\n * @method catch\n * @name catch\n * @owner Observable\n */\nfunction _catch(selector) {\n    return operators_1.catchError(selector)(this);\n}\nexports._catch = _catch;\n","map":{"version":3,"file":"catch.js","sources":["../src/compat/operator/catch.ts"],"names":[],"mappings":";;AAEA,4CAA2D;AAE3D;;;;;;;;;;;;;;;;;;;;;;;;;;;;;;;;;;;;;;;;;;;;;;;;;;;;;;;;;;GA0DG;AACH,SAAgB,MAAM,CAA4B,QAAiE;IACjH,OAAO,sBAAW,CAAC,QAAQ,CAAC,CAAC,IAAI,CAAC,CAAC;AACrC,CAAC;AAFD,wBAEC","sourcesContent":[null]}},"hash":"7ef1de1813a1fc75ff409ca9b3383531","cacheData":{"env":{}}}